<?xml version="1.0" ?>
<robot name="R2" xmlns:xacro="http://www.ros.org/wiki/xacro">

<!-- <xacro:include filename="$(find ros2_livox_simulation)/urdf/mid360.xacro" /> -->
<xacro:include filename="$(find rc2026_field)/urdf/materials.xacro" />
<!-- <xacro:include filename="$(find r2_description)/urdf/R2.trans" /> -->
<xacro:include filename="$(find rc2026_field)/urdf/R2.gazebo" />
<link name="base_link">
  <inertial>
    <origin xyz="0.013939690526257072 -0.000368559794553403 0.02322444965726985" rpy="0 0 0"/>
    <mass value="64.00449387778522"/>
    <inertia ixx="2.356025" iyy="2.917698" izz="4.533519" ixy="0.016778" iyz="-0.041196" ixz="-0.222567"/>
  </inertial>
  <visual>
    <origin xyz="0 0 0" rpy="0 0 0"/>
    <geometry>
      <mesh filename="file://$(find rc2026_field)/meshes/base_link.stl" scale="0.001 0.001 0.001"/>
    </geometry>
    <material name="silver"/>
  </visual>
  <collision>
    <origin xyz="0 0 0" rpy="0 0 0"/>
    <geometry>
      <mesh filename="file://$(find rc2026_field)/meshes/base_link.stl" scale="0.001 0.001 0.001"/>
    </geometry>
  </collision>
</link>

<link name="wheel_1_1">
  <inertial>
    <origin xyz="3.6637359812630166e-15 -0.02999999999999997 -5.204170427930421e-18" rpy="0 0 0"/>
    <mass value="5.289892249930832"/>
    <inertia ixx="0.006381" iyy="0.009588" izz="0.006381" ixy="-0.0" iyz="0.0" ixz="-0.0"/>
  </inertial>
  <visual>
    <origin xyz="-0.225 0.27 -0.01" rpy="0 0 0"/>
    <geometry>
      <mesh filename="file://$(find rc2026_field)/meshes/wheel_1_1.stl" scale="0.001 0.001 0.001"/>
    </geometry>
    <material name="silver"/>
  </visual>
  <collision>
    <origin xyz="0 0 0" rpy="1.570796 0 0"/>
    <geometry>
      <cylinder radius="0.06" length="0.06"/>
    </geometry>
  </collision>
</link>

<link name="wheel_2_1">
  <inertial>
    <origin xyz="3.4416913763379853e-15 -0.02999999999999986 -1.9081958235744878e-17" rpy="0 0 0"/>
    <mass value="5.289892249930832"/>
    <inertia ixx="0.006381" iyy="0.009588" izz="0.006381" ixy="-0.0" iyz="0.0" ixz="0.0"/>
  </inertial>
  <visual>
    <origin xyz="0.225 0.27 -0.01" rpy="0 0 0"/>
    <geometry>
      <mesh filename="file://$(find rc2026_field)/meshes/wheel_2_1.stl" scale="0.001 0.001 0.001"/>
    </geometry>
    <material name="silver"/>
  </visual>
  <collision>
    <origin xyz="0 0 0" rpy="1.570796 0 0"/>
    <geometry>
      <cylinder radius="0.06" length="0.06"/>
    </geometry>
  </collision>
</link>

<link name="wheel_3_1">
  <inertial>
    <origin xyz="3.3861802251067274e-15 0.030000000000000027 -1.9081958235744878e-17" rpy="0 0 0"/>
    <mass value="5.289892249930832"/>
    <inertia ixx="0.006381" iyy="0.009588" izz="0.006381" ixy="-0.0" iyz="-0.0" ixz="0.0"/>
  </inertial>
  <visual>
    <origin xyz="0.225 -0.27 -0.01" rpy="0 0 0"/>
    <geometry>
      <mesh filename="file://$(find rc2026_field)/meshes/wheel_3_1.stl" scale="0.001 0.001 0.001"/>
    </geometry>
    <material name="silver"/>
  </visual>
  <collision>
    <origin xyz="0 0 0" rpy="1.570796 0 0"/>
    <geometry>
      <cylinder radius="0.06" length="0.06"/>
    </geometry>
  </collision>
</link>

<link name="wheel_4_1">
  <inertial>
    <origin xyz="3.6637359812630166e-15 0.02999999999999997 -8.673617379884035e-18" rpy="0 0 0"/>
    <mass value="5.289892249930832"/>
    <inertia ixx="0.006381" iyy="0.009588" izz="0.006381" ixy="0.0" iyz="0.0" ixz="-0.0"/>
  </inertial>
  <visual>
    <origin xyz="-0.225 -0.27 -0.01" rpy="0 0 0"/>
    <geometry>
      <mesh filename="file://$(find rc2026_field)/meshes/wheel_4_1.stl" scale="0.001 0.001 0.001"/>
    </geometry>
    <material name="silver"/>
  </visual>
  <collision>
    <origin xyz="0 0 0" rpy="1.570796 0 0"/>
    <geometry>
      <cylinder radius="0.06" length="0.06"/>
    </geometry>
  </collision>
</link>



<link name="mid360_1">
  <inertial>
    <origin xyz="1.6653345369377348e-16 0.0 0.030000000000000082" rpy="0 0 0"/>
    <mass value="1.6955999999999998"/>
    <inertia ixx="0.001017" iyy="0.001017" izz="0.001017" ixy="0.0" iyz="0.0" ixz="0.0"/>
  </inertial>
  <visual>
    <origin xyz="-0.32015 0.30715 -0.151" rpy="0 0 0"/>
    <geometry>
      <mesh filename="file://$(find rc2026_field)/meshes/mid360_1.stl" scale="0.001 0.001 0.001"/>
    </geometry>
    <material name="silver"/>
  </visual>
  <collision>
    <origin xyz="-0.32015 0.30715 -0.151" rpy="0 0 0"/>
    <geometry>
      <mesh filename="file://$(find rc2026_field)/meshes/mid360_1.stl" scale="0.001 0.001 0.001"/>
    </geometry>
  </collision>
</link>

<!-- <xacro:mid360 name="livox" parent="mid360_1" topic="/livox/lidar">
    <origin xyz="0 0 0" rpy="0 0 0"/>
</xacro:mid360> -->

<link name="camera_link">
  <visual>
    <origin xyz="0 0 0" rpy="0 0 0" />
    <geometry>
      <box size="0.025 0.09 0.025" />
    </geometry>
    <material name="black" />
  </visual>
  <collision>
    <origin xyz="0 0 0" rpy="0 0 0" />
    <geometry>
      <box size="0.025 0.09 0.025" />
    </geometry>
  </collision>
  <inertial>
    <mass value="0.072" />
    <inertia ixx="0.001" ixy="0" ixz="0" iyy="0.001" iyz="0" izz="0.001" />
  </inertial>
</link>

<joint name="camera_joint" type="fixed">
  <parent link="base_link" />
  <child link="camera_link" />
  <origin xyz="0.5 0 0.2" rpy="0 0 0" />
</joint>

<joint name="spin_1" type="continuous">
  <origin xyz="0.225 -0.27 0.01" rpy="0 0 0"/>
  <parent link="base_link"/>
  <child link="wheel_1_1"/>
  <axis xyz="0.0 1.0 0.0"/>
  <dynamics damping="1.0" friction="1.0"/>
</joint>

<joint name="spin_2" type="continuous">
  <origin xyz="-0.225 -0.27 0.01" rpy="0 0 0"/>
  <parent link="base_link"/>
  <child link="wheel_2_1"/>
  <axis xyz="0.0 1.0 0.0"/>
  <dynamics damping="1.0" friction="1.0"/>
</joint>
<joint name="spin_3" type="continuous">
  <origin xyz="-0.225 0.27 0.01" rpy="0 0 0"/>
  <parent link="base_link"/>
  <child link="wheel_3_1"/>
  <axis xyz="0.0 1.0 0.0"/>
  <dynamics damping="1.0" friction="1.0"/>
</joint>
<joint name="spin_4" type="continuous">
  <origin xyz="0.225 0.27 0.01" rpy="0 0 0"/>
  <parent link="base_link"/>
  <child link="wheel_4_1"/>
  <axis xyz="0.0 1.0 0.0"/>
  <dynamics damping="1.0" friction="1.0"/>
</joint>

<joint name="slide_11" type="fixed">
  <origin xyz="0.32015 -0.30715 0.151" rpy="0 0 0"/>
  <parent link="base_link"/>
  <child link="mid360_1"/>
</joint>

</robot>
